<?xml version="1.0" encoding="utf-8"?>
<!-- This URDF was automatically created by SolidWorks to URDF Exporter! Originally created by Stephen Brawner (brawner@gmail.com) 
     Commit Version: 1.6.0-1-g15f4949  Build Version: 1.6.7594.29634
     For more information, please see http://wiki.ros.org/sw_urdf_exporter -->
<robot
  name="krontonbot">
  <link
    name="base_link">
    <inertial>
      <origin
        xyz="-8.53428389885336E-05 -0.00202496133622002 0.059024928729213"
        rpy="0 0 0" />
      <mass
        value="1.16652586484334" />
      <inertia
        ixx="0.00559816194279088"
        ixy="4.88502656787066E-08"
        ixz="-3.25439864111426E-08"
        iyy="0.00608429215928661"
        iyz="1.90242300588512E-07"
        izz="0.01165291250337" />
    </inertial>
    <visual>
      <origin
        xyz="0 0 0"
        rpy="0 0 0" />
      <geometry>
        <mesh
          filename="package://krontonbot_description/meshes/base_link.STL" />
      </geometry>
      <material
        name="">
        <color
          rgba="0.298039215686275 0.298039215686275 0.298039215686275 1" />
      </material>
    </visual>
    <collision>
      <origin
        xyz="0 0 0"
        rpy="0 0 0" />
      <geometry>
        <mesh
          filename="package://krontonbot_description/meshes/base_link.STL" />
      </geometry>
    </collision>
  </link>
  <link
    name="left_wheel">
    <inertial>
      <origin
        xyz="6.2373E-10 -5.5317E-10 3.9908E-05"
        rpy="0 0 0" />
      <mass
        value="0.035175" />
      <inertia
        ixx="1.5237E-05"
        ixy="3.7076E-10"
        ixz="-5.6702E-14"
        iyy="1.5237E-05"
        iyz="4.8698E-14"
        izz="2.5786E-05" />
    </inertial>
    <visual>
      <origin
        xyz="0 0 0"
        rpy="0 0 0" />
      <geometry>
        <mesh
          filename="package://krontonbot_description/meshes/left_wheel.STL" />
      </geometry>
      <material
        name="">
        <color
          rgba="0.75294 0.75294 0.75294 1" />
      </material>
    </visual>
    <collision>
      <origin
        xyz="0 0 0"
        rpy="0 0 0" />
      <geometry>
        <mesh
          filename="package://krontonbot_description/meshes/left_wheel.STL" />
      </geometry>
    </collision>
  </link>
  <joint
    name="left_wheel_joint"
    type="continuous">
    <origin
      xyz="0 0.11511 -0.02"
      rpy="-1.5708 0 -3.1416" />
    <parent
      link="base_link" />
    <child
      link="left_wheel" />
    <axis
      xyz="0 0 -1" />
  </joint>
  <link
    name="right_wheel">
    <inertial>
      <origin
        xyz="8.58566440165021E-10 2.46938719472567E-11 -3.99077934541432E-05"
        rpy="0 0 0" />
      <mass
        value="0.0351748274831478" />
      <inertia
        ixx="1.52367980613616E-05"
        ixy="-3.68845709547513E-10"
        ixz="6.93589578763181E-14"
        iyy="1.52374644129476E-05"
        iyz="-8.10595878360431E-15"
        izz="2.57858861191368E-05" />
    </inertial>
    <visual>
      <origin
        xyz="0 0 0"
        rpy="0 0 0" />
      <geometry>
        <mesh
          filename="package://krontonbot_description/meshes/right_wheel.STL" />
      </geometry>
      <material
        name="">
        <color
          rgba="0.752941176470588 0.752941176470588 0.752941176470588 1" />
      </material>
    </visual>
    <collision>
      <origin
        xyz="0 0 0"
        rpy="0 0 0" />
      <geometry>
        <mesh
          filename="package://krontonbot_description/meshes/right_wheel.STL" />
      </geometry>
    </collision>
  </link>
  <joint
    name="right_wheel_joint"
    type="continuous">
    <origin
      xyz="0 -0.11511 -0.02"
      rpy="-1.5708 0 -3.1416" />
    <parent
      link="base_link" />
    <child
      link="right_wheel" />
    <axis
      xyz="0 0 -1" />
  </joint>
  <link
    name="front_caster">
    <inertial>
      <origin
        xyz="5.49015960071841E-06 -2.77555756156289E-17 0.00855457803590924"
        rpy="0 0 0" />
      <mass
        value="0.14008480560204" />
      <inertia
        ixx="2.2665271657638E-05"
        ixy="8.53942661662015E-22"
        ixz="-3.68962750472619E-09"
        iyy="1.62583470081429E-05"
        iyz="-2.73397173137152E-21"
        izz="3.40965805026056E-05" />
    </inertial>
    <visual>
      <origin
        xyz="0 0 0"
        rpy="0 0 0" />
      <geometry>
        <mesh
          filename="package://krontonbot_description/meshes/front_caster.STL" />
      </geometry>
      <material
        name="">
        <color
          rgba="0.752941176470588 0.752941176470588 0.752941176470588 1" />
      </material>
    </visual>
    <collision>
      <origin
        xyz="0 0 0"
        rpy="0 0 0" />
      <geometry>
        <mesh
          filename="package://krontonbot_description/meshes/front_caster.STL" />
      </geometry>
    </collision>
  </link>
  <joint
    name="front_caster_joint"
    type="fixed">
    <origin
      xyz="0.115 0 -0.046"
      rpy="0 0 0" />
    <parent
      link="base_link" />
    <child
      link="front_caster" />
    <axis
      xyz="0 0 0" />
  </joint>
  <link
    name="back_caster">
    <inertial>
      <origin
        xyz="5.4902E-06 0 0.0085546"
        rpy="0 0 0" />
      <mass
        value="0.14008" />
      <inertia
        ixx="2.2665E-05"
        ixy="-8.4066E-22"
        ixz="-3.6896E-09"
        iyy="1.6258E-05"
        iyz="-2.1779E-21"
        izz="3.4097E-05" />
    </inertial>
    <visual>
      <origin
        xyz="0 0 0"
        rpy="0 0 0" />
      <geometry>
        <mesh
          filename="package://krontonbot_description/meshes/back_caster.STL" />
      </geometry>
      <material
        name="">
        <color
          rgba="0.75294 0.75294 0.75294 1" />
      </material>
    </visual>
    <collision>
      <origin
        xyz="0 0 0"
        rpy="0 0 0" />
      <geometry>
        <mesh
          filename="package://krontonbot_description/meshes/back_caster.STL" />
      </geometry>
    </collision>
  </link>
  <joint
    name="back_caster_joint"
    type="fixed">
    <origin
      xyz="-0.115 0 -0.046"
      rpy="0 0 0" />
    <parent
      link="base_link" />
    <child
      link="back_caster" />
    <axis
      xyz="0 0 0" />
  </joint>
  <link
    name="laser">
    <inertial>
      <origin
        xyz="0.0057997 0.00025825 0.0039383"
        rpy="0 0 0" />
      <mass
        value="0.14299" />
      <inertia
        ixx="4.6252E-05"
        ixy="2.6014E-07"
        ixz="3.6105E-06"
        iyy="7.3499E-05"
        iyz="-3.5217E-07"
        izz="0.00010796" />
    </inertial>
    <visual>
      <origin
        xyz="0 0 0"
        rpy="0 0 0" />
      <geometry>
        <mesh
          filename="package://krontonbot_description/meshes/laser.STL" />
      </geometry>
      <material
        name="">
        <color
          rgba="0.10196 0.10196 0.10196 1" />
      </material>
    </visual>
    <collision>
      <origin
        xyz="0 0 0"
        rpy="0 0 0" />
      <geometry>
        <mesh
          filename="package://krontonbot_description/meshes/laser.STL" />
      </geometry>
    </collision>
  </link>
  <joint
    name="laser_joint"
    type="fixed">
    <origin
      xyz="-0.0014081 0.0017337 0.2161"
      rpy="0 0 0" />
    <parent
      link="base_link" />
    <child
      link="laser" />
    <axis
      xyz="0 0 0" />
  </joint>
  <link
    name="imu_link">
    <inertial>
      <origin
        xyz="0 0 0"
        rpy="0 0 0" />
      <mass
        value="0" />
      <inertia
        ixx="0"
        ixy="0"
        ixz="0"
        iyy="0"
        iyz="0"
        izz="0" />
    </inertial>
    <visual>
      <origin
        xyz="0 0 0"
        rpy="0 0 0" />
      <geometry>
        <mesh
          filename="package://krontonbot_description/meshes/imu_link.STL" />
      </geometry>
      <material
        name="">
        <color
          rgba="1 1 1 1" />
      </material>
    </visual>
    <collision>
      <origin
        xyz="0 0 0"
        rpy="0 0 0" />
      <geometry>
        <mesh
          filename="package://krontonbot_description/meshes/imu_link.STL" />
      </geometry>
    </collision>
  </link>
  <joint
    name="imu_joint"
    type="fixed">
    <origin
      xyz="0.088 0.00010919 -0.008783"
      rpy="0 0 0" />
    <parent
      link="base_link" />
    <child
      link="imu_link" />
    <axis
      xyz="0 1 0" />
    <limit
      lower="0"
      upper="0"
      effort="0"
      velocity="0" />
  </joint>
</robot>